<?xml version="1.0"?>
<!-- source: https://github.com/nalt/wsg50-ros-pkg/tree/master/wsg_50_simulation -->
<robot name="wsg_50" 

       xmlns:xi="http://www.w3.org/2001/XInclude"
       xmlns:gazebo="http://playerstage.sourceforge.net/gazebo/xmlschema/#gz"
       xmlns:model="http://playerstage.sourceforge.net/gazebo/xmlschema/#model"
       xmlns:sensor="http://playerstage.sourceforge.net/gazebo/xmlschema/#sensor"
       xmlns:body="http://playerstage.sourceforge.net/gazebo/xmlschema/#body"
       xmlns:geom="http://playerstage.sourceforge.net/gazebo/xmlschema/#geom"
       xmlns:joint="http://playerstage.sourceforge.net/gazebo/xmlschema/#joint"
       xmlns:interface="http://playerstage.sourceforge.net/gazebo/xmlschema/#interface"
       xmlns:rendering="http://playerstage.sourceforge.net/gazebo/xmlschema/#rendering"
       xmlns:renderable="http://playerstage.sourceforge.net/gazebo/xmlschema/#renderable"
       xmlns:controller="http://playerstage.sourceforge.net/gazebo/xmlschema/#controller"
       xmlns:physics="http://playerstage.sourceforge.net/gazebo/xmlschema/#physics">

  <!-- BASE LINK -->
  <link name="base_link">
    <inertial>
      <mass value="1.2" />
      <origin xyz="0 0 0" />
      <inertia  ixx="1.0" ixy="0.0"  ixz="0.0"  iyy="1.0"  iyz="0.0"  izz="1.0" />
    </inertial>

    <visual>
      <origin xyz="0.0 0 0" rpy="0 0 0" />
      <geometry>
        <mesh filename="./meshes/WSG50_110.stl" scale="1 1 1"/>
      </geometry>
      <material name="grey">
        <color rgba="0.5 0.5 0.5 1"/>
      </material>
    </visual>

    <collision>
      <origin xyz="0.0 0 0" rpy="0 0 0" />
      <geometry>
        <mesh filename="./meshes/WSG50_110.stl" scale="1 1 1"/>
      </geometry>
    </collision>
  </link>

  <!-- GRIPPER LEFT -->

  <joint name="base_joint_gripper_left" type="prismatic">
    <limit lower="-0.055" upper="-0.0027" effort="1.0" velocity="1.0"/>
    <origin xyz="0 0 0" rpy="0 0 0" />      <!--origin xyz="-0.0067 0 0.049" rpy="0 0 0" /-->
    <parent link="base_link"/>
    <child link="gripper_left" />
    <dynamics friction="100" damping="100" />
    <axis xyz="1 0 0"/>
    <limit effort="100" velocity="100"/>
  </joint>

  <link name="gripper_left">
    <inertial>
      <mass value="0.1" />
      <origin xyz="0 0 0" />
      <inertia ixx="1.0" ixy="0.0" ixz="0.0"
                iyy="1.0" iyz="0.0" 
                izz="1.0" />
    </inertial>

    <visual>
      <origin xyz="0.0 0 0" rpy="0 0 0" />
      <geometry>
        <mesh filename="./meshes/GUIDE_WSG50_110.stl" scale="0.001 0.001 0.001"/>
      </geometry>
      <material name="black">
        <color rgba="0 0 0 0"/>
      </material>
    </visual>

    <collision>
      <origin xyz="0 0 0" rpy="0 0 0" />
      <geometry>
        <mesh filename="./meshes/GUIDE_WSG50_110.stl" scale="0.001 0.001 0.001"/>
      </geometry>
    </collision>
  </link>

  <!-- LEFT FINGER -->

  <joint name="guide_joint_finger_left" type="fixed">
    <origin xyz="0 0 0.023" rpy="0 0 0" />
    <parent link="gripper_left"/>
    <child link="finger_left" />
    <dynamics friction="100" damping="100" />
    <axis xyz="1 0 0"/>
    <limit effort="100" velocity="100"/>
  </joint>

  <link name="finger_left">
    <inertial>
      <mass value="0.1" />
      <origin xyz="0 0 0" />
      <inertia ixx="1.0" ixy="0.0" ixz="0.0"
                iyy="1.0" iyz="0.0" 
                izz="1.0" />
    </inertial>

    <visual>
      <origin xyz="0.0 0 0" rpy="0 0 0" />
      <geometry>
        <mesh filename="./meshes/WSG-FMF.stl" scale="0.001 0.001 0.001"/>
      </geometry>
      <material name="black">
        <color rgba="0 0 0 0"/>
      </material>
    </visual>

    <collision>
      <origin xyz="0 0 0" rpy="0 0 0" />
      <geometry>
        <mesh filename="./meshes/WSG-FMF.stl" scale="0.001 0.001 0.001"/>
      </geometry>
    </collision>
  </link>

  <!-- GRIPPER RIGHT -->

  <joint name="base_joint_gripper_right" type="prismatic">
     <limit lower="0.0027" upper="0.055" effort="1.0" velocity="1.0"/>
     <origin xyz="0 0 0" rpy="0 0 3.14159" />
     <parent link="base_link"/>
     <child link="gripper_right" />
     <axis xyz="-1 0 0"/>
     <dynamics friction="100" damping="100" />
     <limit effort="100" velocity="100"/>
  </joint>
	
  <link name="gripper_right">
    <inertial>
      <mass value="0.1" />
      <origin xyz="0 0 0" />
      <inertia ixx="1.0" ixy="0.0" ixz="0.0"
              iyy="1.0" iyz="0.0" 
              izz="1.0" />
    </inertial>

    <visual>
      <origin xyz="0.0 0 0" rpy="0 0 0" />
      <geometry>
        <mesh filename="./meshes/GUIDE_WSG50_110.stl" scale="0.001 0.001 0.001"/>
      </geometry>
      <material name="black">
        <color rgba="0 0 0 0"/>
      </material>
    </visual>

    <collision>
      <origin xyz="0 0 0" rpy="0 0 0" />
      <geometry>
        <mesh filename="./meshes/GUIDE_WSG50_110.stl" scale="0.001 0.001 0.001"/>
      </geometry>
    </collision>
  </link>

  <!-- RIGHT FINGER -->

  <joint name="guide_joint_finger_right" type="fixed">
    <origin xyz="0 0 0.023" rpy="0 0 0" />
    <parent link="gripper_right"/>
    <child link="finger_right" />
    <dynamics friction="100" damping="100" />
    <axis xyz="1 0 0"/>
    <limit effort="100" velocity="100"/>
  </joint>

  <link name="finger_right">
    <inertial>
      <mass value="0.1" />
      <origin xyz="0 0 0" />
      <inertia ixx="1.0" ixy="0.0" ixz="0.0"
                iyy="1.0" iyz="0.0" 
                izz="1.0" />
    </inertial>

    <visual>
      <origin xyz="0.0 0 0" rpy="0 0 0" />
      <geometry>
        <mesh filename="./meshes/WSG-FMF.stl" scale="0.001 0.001 0.001"/>
      </geometry>
      <material name="black">
        <color rgba="0 0 0 0"/>
      </material>
    </visual>

    <collision>
      <origin xyz="0 0 0" rpy="0 0 0" />
      <geometry>
        <mesh filename="./meshes/WSG-FMF.stl" scale="0.001 0.001 0.001"/>
      </geometry>
    </collision>
  </link>

</robot>