<?xml version="1.0"?>
<!-- source: https://github.com/RethinkRobotics/intera_common/tree/master/intera_tools_description/urdf/electric_gripper -->
<robot name="sawyer_2f">
  <link name="base_link">
    <visual>
      <origin rpy="1.5707963 0 0" xyz="0 0 0"/>
      <geometry>
        <mesh filename="meshes/base_vhacd.obj"/> 
      </geometry>
    </visual>
    <collision>
      <origin rpy="1.5707963 0 0" xyz="0 0 0"/>
      <geometry>
        <mesh filename="meshes/base_vhacd.obj"/> 
      </geometry>
    </collision>
    <inertial>
      <origin rpy="1.5707963 0 0" xyz="0 0 0"/>
      <mass value=".1"/>
      <inertia ixx="1" ixy="0" ixz="0" iyy="1" iyz="0" izz="1"/>
    </inertial>
  </link> 
  <link name="leftfinger">
    <visual>
      <origin rpy="0 0 0" xyz="0.0 0.0 0"/>
      <geometry>
        <mesh filename="meshes/standard_narrow_vhacd.obj"/>
      </geometry>
    </visual>
    <collision>
      <origin rpy="0 0 0" xyz="0.0 0.0 0"/>
      <geometry>
        <mesh filename="meshes/standard_narrow_vhacd.obj"/>
      </geometry>
    </collision>
    <inertial>
      <origin rpy="0 0 0" xyz="0.00 -0.0 0"/>
      <mass value=".1"/>
      <inertia ixx="1" ixy="0" ixz="0" iyy="1" iyz="0" izz="1"/>
    </inertial>
  </link>
  <link name="rightfinger">
    <visual>
      <origin rpy="0 0 0" xyz="0.00 0.0 0"/>
        <geometry>
          <mesh filename="meshes/standard_narrow_vhacd.obj"/>
        </geometry>
    </visual>
    <collision>
      <origin rpy="0 0 0" xyz="0.00 0.0 0"/>
        <geometry>
          <mesh filename="meshes/standard_narrow_vhacd.obj"/>
        </geometry>
    </collision>
    <inertial>
      <origin rpy="0 0 0" xyz="0.00 0.0 0"/>
      <mass value=".1"/>
      <inertia ixx="1" ixy="0" ixz="0" iyy="1" iyz="0" izz="1"/>
    </inertial>
  </link>
<joint name="finger_joint1" type="prismatic">
  <parent link="base_link"/>
  <child link="leftfinger"/>
  <origin rpy="0 0 0" xyz="0.003 -0.023 0.04552"/>
  <axis xyz="0 1 0"/>
  <limit effort="20" lower="0.0" upper="0.044" velocity="0.2"/>
</joint>
<joint name="finger_joint2" type="prismatic">
  <parent link="base_link"/>
  <child link="rightfinger"/>
  <origin rpy="0 0 -3.1415926" xyz="0.003 -0.023 0.04552"/>
  <axis xyz="0 -1 0"/>
  <limit effort="20" lower="0.0" upper="0.044" velocity="0.2"/>
</joint>
</robot>
