<?xml version="1.0" ?>
<!-- source: https://github.com/robotlearn/pyrobolearn/blob/master/pyrobolearn/robots/urdfs/franka/franka.urdf -->
<!-- =================================================================================== -->
<!-- |    This document was autogenerated by xacro from panda_arm_hand.urdf.xacro      | -->
<!-- |    EDITING THIS FILE BY HAND IS NOT RECOMMENDED                                 | -->
<!-- =================================================================================== -->
<robot name="panda" xmlns:xacro="http://www.ros.org/wiki/xacro">
  <material name="black">
    <color rgba="0.0 0.0 0.0 1"/>
  </material>
  <material name="white">
    <color rgba="0.9 0.9 0.9 1"/>
  </material>
  <material name="dark_gray">
    <color rgba="0.3 0.3 0.3 1"/>
  </material>
  <material name="gray">
    <color rgba="0.5 0.5 0.5 1"/>
  </material>
  <material name="light_gray">
    <color rgba="0.7 0.7 0.7 1"/>
  </material>
  <material name="pure_red">
    <color rgba="1.0 0.0 0.0 1"/>
  </material>
  <material name="red">
    <color rgba="0.5 0.1 0.2 1"/>
  </material>
  <material name="pure_green">
    <color rgba="0.0 1.0 0.0 1"/>
  </material>
  <material name="pure_blue">
    <color rgba="0.0 0.0 1.0 1"/>
  </material>
  <material name="blue">
    <color rgba="0.0 0.2 0.3 1"/>
  </material>

  <link name="panda_hand">
    <inertial> <!-- these inertia are calculated based on the visual meshes using Meshlab, and using a density of 1kg/m^3 (http://gazebosim.org/tutorials?tut=inertia) -->
      <mass value="1"/> <!-- volume = 0.000488 -->
      <origin xyz="-0.000007 0.001524 0.027591"/>
      <inertia ixx="0.00409836" ixy="0.000000" ixz="0.000000" iyy="0.00061475" iyz="0.000000" izz="0.00409836"/> <!-- divided by the volume, just need to be multiplied by the mass -->
    </inertial>
    <visual>
      <material name="white"/>
      <geometry>
        <mesh filename="meshes/visual/hand.stl"/>
      </geometry>
    </visual>
    <collision>
      <geometry>
        <mesh filename="meshes/collision/hand.stl"/>
      </geometry>
    </collision>
  </link>
  <link name="panda_leftfinger">
    <inertial> <!-- these inertia are calculated based on the visual meshes using Meshlab, and using a density of 1kg/m^3 (http://gazebosim.org/tutorials?tut=inertia) -->
      <mass value="1"/>
      <origin xyz="0.000002 0.014564 0.022794"/>
      <inertia ixx="0.00030727" ixy="0.000000" ixz="0.000000" iyy="0.00003018" iyz="0.00005455" izz="0.00007091"/> <!-- divided by the volume, just need to be multiplied by the mass -->
    </inertial>
    <visual>
      <material name="light_gray"/>
      <geometry>
        <mesh filename="meshes/visual/finger.stl"/>
      </geometry>
    </visual>
    <collision>
      <geometry>
        <mesh filename="meshes/visual/finger.stl"/>
      </geometry>
    </collision>
  </link>
  <link name="panda_rightfinger">
    <inertial> <!-- these inertia are calculated based on the visual meshes using Meshlab, and using a density of 1kg/m^3 (http://gazebosim.org/tutorials?tut=inertia) -->
      <mass value="1"/> <!-- volume = 0.000011 -->
      <origin xyz="0.000002 0.014564 0.022794"/>
      <inertia ixx="0.00030727" ixy="0.000000" ixz="0.000000" iyy="0.00003018" iyz="0.00005455" izz="0.00007091"/> <!-- divided by the volume, just need to be multiplied by the mass -->
    </inertial>
    <visual>
      <material name="light_gray"/>
      <origin rpy="0 0 3.14159265359" xyz="0 0 0"/>
      <geometry>
        <mesh filename="meshes/visual/finger.stl"/>
      </geometry>
    </visual>
    <collision>
      <origin rpy="0 0 3.14159265359" xyz="0 0 0"/>
      <geometry>
        <mesh filename="meshes/visual/finger.stl"/>
      </geometry>
    </collision>
  </link>
  <joint name="panda_finger_joint1" type="prismatic">
    <parent link="panda_hand"/>
    <child link="panda_leftfinger"/>
    <origin rpy="0 0 0" xyz="0 0 0.0584"/>
    <axis xyz="0 1 0"/>
    <limit effort="20" lower="0.0" upper="0.04" velocity="0.2"/>
  </joint>
  <joint name="panda_finger_joint2" type="prismatic">
    <parent link="panda_hand"/>
    <child link="panda_rightfinger"/>
    <origin rpy="0 0 0" xyz="0 0 0.0584"/>
    <axis xyz="0 -1 0"/>
    <limit effort="20" lower="0.0" upper="0.04" velocity="0.2"/>
    <mimic joint="panda_finger_joint1"/>
  </joint>
</robot>

