<?xml version="1.0" ?>
<!-- source: https://github.com/SAKErobotics/EZGripper/tree/master/ezgripper_driver -->
<!-- =================================================================================== -->
<!-- |    This document was autogenerated by xacro from /home/beichun/research/grasp/catkin_ws/src/EZGripper/ezgripper_driver/urdf/ezgripper_dual_gen2_standalone.urdf.xacro | -->
<!-- |    EDITING THIS FILE BY HAND IS NOT RECOMMENDED                                 | -->
<!-- =================================================================================== -->
<robot name="ezgripper_stand_alone" xmlns:xacro="http://ros.org/wiki/xacro">
  <!-- links -->
  <link name="left_ezgripper_palm_link">
    <visual>
      <origin rpy="0 0 0" xyz="0 0 0"/>
      <geometry>
        <mesh filename="meshes/SAKE_Palm_Dual_Gen2.stl"/>
      </geometry>
    </visual>
    <collision>
      <origin rpy="0 0 0" xyz="0 0 0"/>
      <geometry>
        <mesh filename="meshes/SAKE_Palm_Dual_Gen2.stl"/>
      </geometry>
    </collision>
    <inertial>
      <mass value=".3"/>
      <inertia ixx="0.01" ixy="0.0" ixz="0.0" iyy="0.01" iyz="0.0" izz="0.01"/>
    </inertial>
  </link>
  <joint name="left_ezgripper_connect" type="fixed">
    <origin rpy="0 0 0" xyz="0.0 0.0 0.0"/>
    <parent link="base_link"/>
    <child link="left_ezgripper_palm_link"/>
    <axis xyz="0 0 0"/>
    <limit effort="0" lower="-1.57075" upper="0.25" velocity="3.67"/>
  </joint>
  <link name="left_ezgripper_finger_L1_1">
    <visual>
      <origin rpy="0 0 0" xyz="0 0 0"/>
      <geometry>
        <mesh filename="meshes/SAKE_Finger_L1_Gen2.stl"/>
      </geometry>
    </visual>
    <collision>
      <origin rpy="0 0 0" xyz="0 0 0"/>
      <geometry>
        <mesh filename="meshes/SAKE_Finger_L1_Gen2.stl"/>
      </geometry>
    </collision>
    <inertial>
      <mass value=".025"/>
      <inertia ixx="0.01" ixy="0.0" ixz="0.0" iyy="0.01" iyz="0.0" izz="0.01"/>
    </inertial>
  </link>
  <link name="left_ezgripper_finger_L1_2">
    <visual>
      <origin rpy="0 0 0" xyz="0 0 0"/>
      <geometry>
        <mesh filename="meshes/SAKE_Finger_L1_Gen2.stl"/>
      </geometry>
    </visual>
    <collision>
      <origin rpy="0 0 0" xyz="0 0 0"/>
      <geometry>
        <mesh filename="meshes/SAKE_Finger_L1_Gen2.stl"/>
      </geometry>
    </collision>
    <inertial>
      <mass value=".025"/>
      <inertia ixx="0.01" ixy="0.0" ixz="0.0" iyy="0.01" iyz="0.0" izz="0.01"/>
    </inertial>
  </link>
  <link name="left_ezgripper_finger_L2_1">
    <visual>
      <origin rpy="0 0 0" xyz="0 0 0"/>
      <geometry>
        <mesh filename="meshes/SAKE_Finger_L2_Gen2.stl"/>
      </geometry>
    </visual>
    <collision>
      <origin rpy="0 0 0" xyz="0 0 0"/>
      <geometry>
        <mesh filename="meshes/SAKE_Finger_L2_Gen2.stl"/>
      </geometry>
    </collision>
    <inertial>
      <mass value=".025"/>
      <inertia ixx="0.01" ixy="0.0" ixz="0.0" iyy="0.01" iyz="0.0" izz="0.01"/>
    </inertial>
  </link>
  <link name="left_ezgripper_finger_L2_2">
    <visual>
      <origin rpy="0 0 0" xyz="0 0 0"/>
      <geometry>
        <mesh filename="meshes/SAKE_Finger_L2_Gen2.stl"/>
      </geometry>
    </visual>
    <collision>
      <origin rpy="0 0 0" xyz="0 0 0"/>
      <geometry>
        <mesh filename="meshes/SAKE_Finger_L2_Gen2.stl"/>
      </geometry>
    </collision>
    <inertial>
      <mass value=".025"/>
      <inertia ixx="0.01" ixy="0.0" ixz="0.0" iyy="0.01" iyz="0.0" izz="0.01"/>
    </inertial>
  </link>
  <joint name="left_ezgripper_knuckle_palm_L1_1" type="revolute">
    <parent link="left_ezgripper_palm_link"/>
    <child link="left_ezgripper_finger_L1_1"/>
    <origin rpy="-1.5708 0 1.57075" xyz="0.072569 0.03 0"/>
    <axis xyz="0 1 0"/>
    <limit effort="1" lower="0" upper="1.94" velocity="3.67"/>
  </joint>
  <joint name="left_ezgripper_knuckle_palm_L1_2" type="revolute">
    <parent link="left_ezgripper_palm_link"/>
    <child link="left_ezgripper_finger_L1_2"/>
    <origin rpy="1.5708 0 -1.57075" xyz="0.072569 -0.03 0"/>
    <axis xyz="0 1 0"/>
    <limit effort="1" lower="0" upper="1.94" velocity="3.67"/>
    <mimic joint="left_ezgripper_knuckle_palm_L1_1"/>
  </joint>
  <joint name="left_ezgripper_knuckle_L1_L2_1" type="revolute">
    <parent link="left_ezgripper_finger_L1_1"/>
    <child link="left_ezgripper_finger_L2_1"/>
    <origin rpy="0 0 0" xyz="0.052 0 0"/>
    <axis xyz="0 1 0"/>
    <limit effort="1" lower="0" upper="1.94" velocity="3.67"/>
  </joint>
  <joint name="left_ezgripper_knuckle_L1_L2_2" type="revolute">
    <parent link="left_ezgripper_finger_L1_2"/>
    <child link="left_ezgripper_finger_L2_2"/>
    <origin rpy="0 0 0" xyz="0.052 0 0"/>
    <axis xyz="0 1 0"/>
    <limit effort="1" lower="0" upper="1.94" velocity="3.67"/>
    <mimic joint="left_ezgripper_knuckle_L1_L2_1"/>
  </joint>
  <transmission name="left_ezgripper_trans_L1_L2_1">
    <type>transmission_interface/SimpleTransmission</type>
    <joint name="left_ezgripper_knuckle_L1_L2_1">
      <hardwareInterface>hardware_interface/PositionJointInterface</hardwareInterface>
    </joint>
    <actuator name="left_ezgripper_motorL1_L2_1">
      <mechanicalReduction>1</mechanicalReduction>
      <hardwareInterface>hardware_interface/PositionJointInterface</hardwareInterface>
    </actuator>
  </transmission>
  <gazebo>
    <plugin filename="libgazebo_ros_joint_state_publisher.so" name="joint_state_publisher">
      <jointName>left_ezgripper_knuckle_L1_L2_1,left_ezgripper_knuckle_L1_L2_2</jointName>
    </plugin>
  </gazebo>
  <link name="world"/>
  <joint name="fixed" type="fixed">
    <parent link="world"/>
    <child link="base_link"/>
  </joint>
  <link name="base_link">
    <inertial>
        <mass value="0" />
        <origin xyz="0 0 0" />
        <inertia  ixx="1.0" ixy="0.0"  ixz="0.0"  iyy="1.0"  iyz="0.0"  izz="1.0" />
    </inertial>

  </link>
</robot>
